Workbook
Name proyAnterior: #REF!

Sheet dummys
A1: id | B1: nombres | C1: Division | D1: grupos | E1: Grupo | F1: Subgrupo | G1: Clase | H1: Subclase | I1: Articulo | J1: Subyacente | K1: NoSubyacente | L1: Transables | M1: NoTransables | N1: Bienes | O1: Servicios | P1: Alimentos | Q1: Transporte | R1: Vivienda | S1: Resto | T1: Nuevos | U1: codigo_articulo | V1: posicion | W1: PonderacionIPC
A2: 01 | B2: Alimentos y Bebidas No Alcohólicas | C2: Grupo | D2: Alimentos y Bebidas No Alcohólicas | E2: 1 | F2: 0 | G2: 0 | H2: 0 | I2: 0 | J2: 0 | K2: =IF(I2=1,IF(J2=1,0,1),0) -> 0 | L2: 0 | M2: =IF(I2=1,IF(L2=1,0,1),0) -> 0 | N2: 0 | O2: =IF(I2=1,IF(N2=1,0,1),0) -> 0 | P2: 0 | Q2: 0 | R2: 0 | S2: 0 | T2: 0 | V2: 3 | W2: 23.835128
A3: 011 | B3: Alimentos | C3: Subgrupo | D3: Alimentos y Bebidas No Alcohólicas | E3: 0 | F3: 1 | G3: 0 | H3: 0 | I3: 0 | J3: 0 | K3: =IF(I3=1,IF(J3=1,0,1),0) -> 0 | L3: 0 | M3: =IF(I3=1,IF(L3=1,0,1),0) -> 0 | N3: 0 | O3: =IF(I3=1,IF(N3=1,0,1),0) -> 0 | P3: 0 | Q3: 0 | R3: 0 | S3: 0 | T3: 0 | V3: 4 | W3: 21.043777
A4: 0111 | B4: Pan y cereales | C4: Clase | D4: Alimentos y Bebidas No Alcohólicas | E4: 0 | F4: 0 | G4: 1 | H4: 0 | I4: 0 | J4: 0 | K4: =IF(I4=1,IF(J4=1,0,1),0) -> 0 | L4: 0 | M4: =IF(I4=1,IF(L4=1,0,1),0) -> 0 | N4: 0 | O4: =IF(I4=1,IF(N4=1,0,1),0) -> 0 | P4: 0 | Q4: 0 | R4: 0 | S4: 0 | T4: 0 | V4: 5 | W4: 3.7578868
A5: 01111 | B5: Pan | C5: SubClase | D5: Alimentos y Bebidas No Alcohólicas | E5: 0 | F5: 0 | G5: 0 | H5: 1 | I5: 0 | J5: 0 | K5: =IF(I5=1,IF(J5=1,0,1),0) -> 0 | L5: 0 | M5: =IF(I5=1,IF(L5=1,0,1),0) -> 0 | N5: 0 | O5: =IF(I5=1,IF(N5=1,0,1),0) -> 0 | P5: 0 | Q5: 0 | R5: 0 | S5: 0 | T5: 0 | V5: 6 | W5: 0.94491769
A6: 0111101 | B6: Pan sobado | C6: Articulo | D6: Alimentos y Bebidas No Alcohólicas | E6: 0 | F6: 0 | G6: 0 | H6: 0 | I6: 1 | J6: 1 | K6: =IF(I6=1,IF(J6=1,0,1),0) -> 0 | L6: 0 | M6: =IF(I6=1,IF(L6=1,0,1),0) -> 1 | N6: 1 | O6: =IF(I6=1,IF(N6=1,0,1),0) -> 0 | P6: 1 | Q6: 0 | R6: 0 | S6: 0 | T6: 0 | U6: IPC_001 | V6: 7 | W6: 0.50544517
A7: 0111102 | B7: Pan de agua | C7: Articulo | D7: Alimentos y Bebidas No Alcohólicas | E7: 0 | F7: 0 | G7: 0 | H7: 0 | I7: 1 | J7: 1 | K7: =IF(I7=1,IF(J7=1,0,1),0) -> 0 | L7: 0 | M7: =IF(I7=1,IF(L7=1,0,1),0) -> 1 | N7: 1 | O7: =IF(I7=1,IF(N7=1,0,1),0) -> 0 | P7: 1 | Q7: 0 | R7: 0 | S7: 0 | T7: 0 | U7: IPC_002 | V7: 8 | W7: 0.39901799
A8: 0111104 | B8: Pan Integral | C8: Articulo | D8: Alimentos y Bebidas No Alcohólicas | E8: 0 | F8: 0 | G8: 0 | H8: 0 | I8: 1 | J8: 1 | K8: =IF(I8=1,IF(J8=1,0,1),0) -> 0 | L8: 1 | M8: =IF(I8=1,IF(L8=1,0,1),0) -> 0 | N8: 1 | O8: =IF(I8=1,IF(N8=1,0,1),0) -> 0 | P8: 1 | Q8: 0 | R8: 0 | S8: 0 | T8: 1 | U8: IPC_003 | V8: 9 | W8: 0.040454533
A9: 01112 | B9: Galletas y productos de panadería | C9: SubClase | D9: Alimentos y Bebidas No Alcohólicas | E9: 0 | F9: 0 | G9: 0 | H9: 1 | I9: 0 | J9: 0 | K9: =IF(I9=1,IF(J9=1,0,1),0) -> 0 | L9: 0 | M9: =IF(I9=1,IF(L9=1,0,1),0) -> 0 | N9: 0 | O9: =IF(I9=1,IF(N9=1,0,1),0) -> 0 | P9: 0 | Q9: 0 | R9: 0 | S9: 0 | T9: 0 | V9: 10 | W9: 0.37196575
A10: 0111201 | B10: Galletas saladas | C10: Articulo | D10: Alimentos y Bebidas No Alcohólicas | E10: 0 | F10: 0 | G10: 0 | H10: 0 | I10: 1 | J10: 1 | K10: =IF(I10=1,IF(J10=1,0,1),0) -> 0 | L10: 1 | M10: =IF(I10=1,IF(L10=1,0,1),0) -> 0 | N10: 1 | O10: =IF(I10=1,IF(N10=1,0,1),0) -> 0 | P10: 1 | Q10: 0 | R10: 0 | S10: 0 | T10: 0 | U10: IPC_004 | V10: 11 | W10: 0.13258761
A11: 0111202 | B11: Bizcochos | C11: Articulo | D11: Alimentos y Bebidas No Alcohólicas | E11: 0 | F11: 0 | G11: 0 | H11: 0 | I11: 1 | J11: 1 | K11: =IF(I11=1,IF(J11=1,0,1),0) -> 0 | L11: 1 | M11: =IF(I11=1,IF(L11=1,0,1),0) -> 0 | N11: 1 | O11: =IF(I11=1,IF(N11=1,0,1),0) -> 0 | P11: 1 | Q11: 0 | R11: 0 | S11: 0 | T11: 0 | U11: IPC_005 | V11: 12 | W11: 0.077885033
A12: 0111203 | B12: Galletas dulces | C12: Articulo | D12: Alimentos y Bebidas No Alcohólicas | E12: 0 | F12: 0 | G12: 0 | H12: 0 | I12: 1 | J12: 1 | K12: =IF(I12=1,IF(J12=1,0,1),0) -> 0 | L12: 1 | M12: =IF(I12=1,IF(L12=1,0,1),0) -> 0 | N12: 1 | O12: =IF(I12=1,IF(N12=1,0,1),0) -> 0 | P12: 1 | Q12: 0 | R12: 0 | S12: 0 | T12: 0 | U12: IPC_006 | V12: 13 | W12: 0.071040732
A13: 0111204 | B13: Galletas de harina | C13: Articulo | D13: Alimentos y Bebidas No Alcohólicas | E13: 0 | F13: 0 | G13: 0 | H13: 0 | I13: 1 | J13: 1 | K13: =IF(I13=1,IF(J13=1,0,1),0) -> 0 | L13: 0 | M13: =IF(I13=1,IF(L13=1,0,1),0) -> 1 | N13: 1 | O13: =IF(I13=1,IF(N13=1,0,1),0) -> 0 | P13: 1 | Q13: 0 | R13: 0 | S13: 0 | T13: 0 | U13: IPC_007 | V13: 14 | W13: 0.020645883
A14: 0111205 | B14: Galletas de soda | C14: Articulo | D14: Alimentos y Bebidas No Alcohólicas | E14: 0 | F14: 0 | G14: 0 | H14: 0 | I14: 1 | J14: 1 | K14: =IF(I14=1,IF(J14=1,0,1),0) -> 0 | L14: 1 | M14: =IF(I14=1,IF(L14=1,0,1),0) -> 0 | N14: 1 | O14: =IF(I14=1,IF(N14=1,0,1),0) -> 0 | P14: 1 | Q14: 0 | R14: 0 | S14: 0 | T14: 0 | U14: IPC_008 | V14: 15 | W14: 0.050453635
A15: 0111206 | B15: Galletas integrales | C15: Articulo | D15: Alimentos y Bebidas No Alcohólicas | E15: 0 | F15: 0 | G15: 0 | H15: 0 | I15: 1 | J15: 1 | K15: =IF(I15=1,IF(J15=1,0,1),0) -> 0 | L15: 1 | M15: =IF(I15=1,IF(L15=1,0,1),0) -> 0 | N15: 1 | O15: =IF(I15=1,IF(N15=1,0,1),0) -> 0 | P15: 1 | Q15: 0 | R15: 0 | S15: 0 | T15: 1 | U15: IPC_009 | V15: 16 | W15: 0.019352848
A16: 01113 | B16: Cereales y harinas | C16: SubClase | D16: Alimentos y Bebidas No Alcohólicas | E16: 0 | F16: 0 | G16: 0 | H16: 1 | I16: 0 | J16: 0 | K16: =IF(I16=1,IF(J16=1,0,1),0) -> 0 | L16: 0 | M16: =IF(I16=1,IF(L16=1,0,1),0) -> 0 | N16: 0 | O16: =IF(I16=1,IF(N16=1,0,1),0) -> 0 | P16: 0 | Q16: 0 | R16: 0 | S16: 0 | T16: 0 | V16: 17 | W16: 0.29698676
A17: 0111301 | B17: Corn Flakes | C17: Articulo | D17: Alimentos y Bebidas No Alcohólicas | E17: 0 | F17: 0 | G17: 0 | H17: 0 | I17: 1 | J17: 1 | K17: =IF(I17=1,IF(J17=1,0,1),0) -> 0 | L17: 1 | M17: =IF(I17=1,IF(L17=1,0,1),0) -> 0 | N17: 1 | O17: =IF(I17=1,IF(N17=1,0,1),0) -> 0 | P17: 1 | Q17: 0 | R17: 0 | S17: 0 | T17: 0 | U17: IPC_010 | V17: 18 | W17: 0.10689881
A18: 0111302 | B18: Avena | C18: Articulo | D18: Alimentos y Bebidas No Alcohólicas | E18: 0 | F18: 0 | G18: 0 | H18: 0 | I18: 1 | J18: 1 | K18: =IF(I18=1,IF(J18=1,0,1),0) -> 0 | L18: 1 | M18: =IF(I18=1,IF(L18=1,0,1),0) -> 0 | N18: 1 | O18: =IF(I18=1,IF(N18=1,0,1),0) -> 0 | P18: 1 | Q18: 0 | R18: 0 | S18: 0 | T18: 0 | U18: IPC_011 | V18: 19 | W18: 0.071995783
A19: 0111303 | B19: Harina de maíz | C19: Articulo | D19: Alimentos y Bebidas No Alcohólicas | E19: 0 | F19: 0 | G19: 0 | H19: 0 | I19: 1 | J19: 1 | K19: =IF(I19=1,IF(J19=1,0,1),0) -> 0 | L19: 1 | M19: =IF(I19=1,IF(L19=1,0,1),0) -> 0 | N19: 1 | O19: =IF(I19=1,IF(N19=1,0,1),0) -> 0 | P19: 1 | Q19: 0 | R19: 0 | S19: 0 | T19: 0 | U19: IPC_012 | V19: 20 | W19: 0.043458139
A20: 0111304 | B20: Harina de trigo | C20: Articulo | D20: Alimentos y Bebidas No Alcohólicas | E20: 0 | F20: 0 | G20: 0 | H20: 0 | I20: 1 | J20: 1 | K20: =IF(I20=1,IF(J20=1,0,1),0) -> 0 | L20: 1 | M20: =IF(I20=1,IF(L20=1,0,1),0) -> 0 | N20: 1 | O20: =IF(I20=1,IF(N20=1,0,1),0) -> 0 | P20: 1 | Q20: 0 | R20: 0 | S20: 0 | T20: 0 | U20: IPC_013 | V20: 21 | W20: 0.053838891
A21: 0111305 | B21: Cereales envasados | C21: Articulo | D21: Alimentos y Bebidas No Alcohólicas | E21: 0 | F21: 0 | G21: 0 | H21: 0 | I21: 1 | J21: 1 | K21: =IF(I21=1,IF(J21=1,0,1),0) -> 0 | L21: 1 | M21: =IF(I21=1,IF(L21=1,0,1),0) -> 0 | N21: 1 | O21: =IF(I21=1,IF(N21=1,0,1),0) -> 0 | P21: 1 | Q21: 0 | R21: 0 | S21: 0 | T21: 1 | U21: IPC_014 | V21: 22 | W21: 0.020795139
A22: 01114 | B22: Arroz | C22: SubClase | D22: Alimentos y Bebidas No Alcohólicas | E22: 0 | F22: 0 | G22: 0 | H22: 1 | I22: 0 | J22: 0 | K22: =IF(I22=1,IF(J22=1,0,1),0) -> 0 | L22: 0 | M22: =IF(I22=1,IF(L22=1,0,1),0) -> 0 | N22: 0 | O22: =IF(I22=1,IF(N22=1,0,1),0) -> 0 | P22: 0 | Q22: 0 | R22: 0 | S22: 0 | T22: 0 | V22: 23 | W22: 1.9448329
A23: 0111401 | B23: Arroz | C23: Articulo | D23: Alimentos y Bebidas No Alcohólicas | E23: 0 | F23: 0 | G23: 0 | H23: 0 | I23: 1 | J23: 0 | K23: =IF(I23=1,IF(J23=1,0,1),0) -> 1 | L23: 0 | M23: =IF(I23=1,IF(L23=1,0,1),0) -> 1 | N23: 1 | O23: =IF(I23=1,IF(N23=1,0,1),0) -> 0 | P23: 1 | Q23: 0 | R23: 0 | S23: 0 | T23: 0 | U23: IPC_015 | V23: 24 | W23: 1.9448329
A24: 01115 | B24: Pastas alimenticias | C24: SubClase | D24: Alimentos y Bebidas No Alcohólicas | E24: 0 | F24: 0 | G24: 0 | H24: 1 | I24: 0 | J24: 0 | K24: =IF(I24=1,IF(J24=1,0,1),0) -> 0 | L24: 0 | M24: =IF(I24=1,IF(L24=1,0,1),0) -> 0 | N24: 0 | O24: =IF(I24=1,IF(N24=1,0,1),0) -> 0 | P24: 0 | Q24: 0 | R24: 0 | S24: 0 | T24: 0 | V24: 25 | W24: 0.19918367
A25: 0111501 | B25: Spaghetti | C25: Articulo | D25: Alimentos y Bebidas No Alcohólicas | E25: 0 | F25: 0 | G25: 0 | H25: 0 | I25: 1 | J25: 1 | K25: =IF(I25=1,IF(J25=1,0,1),0) -> 0 | L25: 1 | M25: =IF(I25=1,IF(L25=1,0,1),0) -> 0 | N25: 1 | O25: =IF(I25=1,IF(N25=1,0,1),0) -> 0 | P25: 1 | Q25: 0 | R25: 0 | S25: 0 | T25: 0 | U25: IPC_016 | V25: 26 | W25: 0.11647762
A26: 0111502 | B26: Fideos | C26: Articulo | D26: Alimentos y Bebidas No Alcohólicas | E26: 0 | F26: 0 | G26: 0 | H26: 0 | I26: 1 | J26: 1 | K26: =IF(I26=1,IF(J26=1,0,1),0) -> 0 | L26: 1 | M26: =IF(I26=1,IF(L26=1,0,1),0) -> 0 | N26: 1 | O26: =IF(I26=1,IF(N26=1,0,1),0) -> 0 | P26: 1 | Q26: 0 | R26: 0 | S26: 0 | T26: 0 | U26: IPC_017 | V26: 27 | W26: 0.051966374
A27: 0111503 | B27: Pastas cortas | C27: Articulo | D27: Alimentos y Bebidas No Alcohólicas | E27: 0 | F27: 0 | G27: 0 | H27: 0 | I27: 1 | J27: 1 | K27: =IF(I27=1,IF(J27=1,0,1),0) -> 0 | L27: 1 | M27: =IF(I27=1,IF(L27=1,0,1),0) -> 0 | N27: 1 | O27: =IF(I27=1,IF(N27=1,0,1),0) -> 0 | P27: 1 | Q27: 0 | R27: 0 | S27: 0 | T27: 1 | U27: IPC_018 | V27: 28 | W27: 0.030739679
A28: 0112 | B28: Carnes | C28: Clase | D28: Alimentos y Bebidas No Alcohólicas | E28: 0 | F28: 0 | G28: 1 | H28: 0 | I28: 0 | J28: 0 | K28: =IF(I28=1,IF(J28=1,0,1),0) -> 0 | L28: 0 | M28: =IF(I28=1,IF(L28=1,0,1),0) -> 0 | N28: 0 | O28: =IF(I28=1,IF(N28=1,0,1),0) -> 0 | P28: 0 | Q28: 0 | R28: 0 | S28: 0 | T28: 0 | V28: 29 | W28: 5.2990782
A29: 01121 | B29: Carne de res | C29: SubClase | D29: Alimentos y Bebidas No Alcohólicas | E29: 0 | F29: 0 | G29: 0 | H29: 1 | I29: 0 | J29: 0 | K29: =IF(I29=1,IF(J29=1,0,1),0) -> 0 | L29: 0 | M29: =IF(I29=1,IF(L29=1,0,1),0) -> 0 | N29: 0 | O29: =IF(I29=1,IF(N29=1,0,1),0) -> 0 | P29: 0 | Q29: 0 | R29: 0 | S29: 0 | T29: 0 | V29: 30 | W29: 0.57658004
A30: 0112101 | B30: Carne corriente de res | C30: Articulo | D30: Alimentos y Bebidas No Alcohólicas | E30: 0 | F30: 0 | G30: 0 | H30: 0 | I30: 1 | J30: 1 | K30: =IF(I30=1,IF(J30=1,0,1),0) -> 0 | L30: 1 | M30: =IF(I30=1,IF(L30=1,0,1),0) -> 0 | N30: 1 | O30: =IF(I30=1,IF(N30=1,0,1),0) -> 0 | P30: 1 | Q30: 0 | R30: 0 | S30: 0 | T30: 0 | U30: IPC_019 | V30: 31 | W30: 0.45328811
A31: 0112102 | B31: Carne de bola | C31: Articulo | D31: Alimentos y Bebidas No Alcohólicas | E31: 0 | F31: 0 | G31: 0 | H31: 0 | I31: 1 | J31: 1 | K31: =IF(I31=1,IF(J31=1,0,1),0) -> 0 | L31: 1 | M31: =IF(I31=1,IF(L31=1,0,1),0) -> 0 | N31: 1 | O31: =IF(I31=1,IF(N31=1,0,1),0) -> 0 | P31: 1 | Q31: 0 | R31: 0 | S31: 0 | T31: 0 | U31: IPC_020 | V31: 32 | W31: 0.028030455
A32: 0112103 | B32: Carne molida de res | C32: Articulo | D32: Alimentos y Bebidas No Alcohólicas | E32: 0 | F32: 0 | G32: 0 | H32: 0 | I32: 1 | J32: 1 | K32: =IF(I32=1,IF(J32=1,0,1),0) -> 0 | L32: 1 | M32: =IF(I32=1,IF(L32=1,0,1),0) -> 0 | N32: 1 | O32: =IF(I32=1,IF(N32=1,0,1),0) -> 0 | P32: 1 | Q32: 0 | R32: 0 | S32: 0 | T32: 0 | U32: IPC_021 | V32: 33 | W32: 0.095261474
A33: 01122 | B33: Carne de aves | C33: SubClase | D33: Alimentos y Bebidas No Alcohólicas | E33: 0 | F33: 0 | G33: 0 | H33: 1 | I33: 0 | J33: 0 | K33: =IF(I33=1,IF(J33=1,0,1),0) -> 0 | L33: 0 | M33: =IF(I33=1,IF(L33=1,0,1),0) -> 0 | N33: 0 | O33: =IF(I33=1,IF(N33=1,0,1),0) -> 0 | P33: 0 | Q33: 0 | R33: 0 | S33: 0 | T33: 0 | V33: 34 | W33: 2.4568069
A34: 0112201 | B34: Pollo fresco | C34: Articulo | D34: Alimentos y Bebidas No Alcohólicas | E34: 0 | F34: 0 | G34: 0 | H34: 0 | I34: 1 | J34: 0 | K34: =IF(I34=1,IF(J34=1,0,1),0) -> 1 | L34: 0 | M34: =IF(I34=1,IF(L34=1,0,1),0) -> 1 | N34: 1 | O34: =IF(I34=1,IF(N34=1,0,1),0) -> 0 | P34: 1 | Q34: 0 | R34: 0 | S34: 0 | T34: 0 | U34: IPC_022 | V34: 35 | W34: 2.3299065
A35: 0112202 | B35: Carne de gallina | C35: Articulo | D35: Alimentos y Bebidas No Alcohólicas | E35: 0 | F35: 0 | G35: 0 | H35: 0 | I35: 1 | J35: 0 | K35: =IF(I35=1,IF(J35=1,0,1),0) -> 1 | L35: 0 | M35: =IF(I35=1,IF(L35=1,0,1),0) -> 1 | N35: 1 | O35: =IF(I35=1,IF(N35=1,0,1),0) -> 0 | P35: 1 | Q35: 0 | R35: 0 | S35: 0 | T35: 0 | U35: IPC_023 | V35: 36 | W35: 0.059928253
A36: 0112203 | B36: Pechuga de pollo | C36: Articulo | D36: Alimentos y Bebidas No Alcohólicas | E36: 0 | F36: 0 | G36: 0 | H36: 0 | I36: 1 | J36: 0 | K36: =IF(I36=1,IF(J36=1,0,1),0) -> 1 | L36: 0 | M36: =IF(I36=1,IF(L36=1,0,1),0) -> 1 | N36: 1 | O36: =IF(I36=1,IF(N36=1,0,1),0) -> 0 | P36: 1 | Q36: 0 | R36: 0 | S36: 0 | T36: 1 | U36: IPC_024 | V36: 37 | W36: 0.066972124
A37: 01123 | B37: Carne de cerdo | C37: SubClase | D37: Alimentos y Bebidas No Alcohólicas | E37: 0 | F37: 0 | G37: 0 | H37: 1 | I37: 0 | J37: 0 | K37: =IF(I37=1,IF(J37=1,0,1),0) -> 0 | L37: 0 | M37: =IF(I37=1,IF(L37=1,0,1),0) -> 0 | N37: 0 | O37: =IF(I37=1,IF(N37=1,0,1),0) -> 0 | P37: 0 | Q37: 0 | R37: 0 | S37: 0 | T37: 0 | V37: 38 | W37: 0.58121541
A38: 0112301 | B38: Carne corriente de cerdo | C38: Articulo | D38: Alimentos y Bebidas No Alcohólicas | E38: 0 | F38: 0 | G38: 0 | H38: 0 | I38: 1 | J38: 1 | K38: =IF(I38=1,IF(J38=1,0,1),0) -> 0 | L38: 1 | M38: =IF(I38=1,IF(L38=1,0,1),0) -> 0 | N38: 1 | O38: =IF(I38=1,IF(N38=1,0,1),0) -> 0 | P38: 1 | Q38: 0 | R38: 0 | S38: 0 | T38: 0 | U38: IPC_025 | V38: 39 | W38: 0.47122464
A39: 0112302 | B39: Chuleta de cerdo | C39: Articulo | D39: Alimentos y Bebidas No Alcohólicas | E39: 0 | F39: 0 | G39: 0 | H39: 0 | I39: 1 | J39: 1 | K39: =IF(I39=1,IF(J39=1,0,1),0) -> 0 | L39: 1 | M39: =IF(I39=1,IF(L39=1,0,1),0) -> 0 | N39: 1 | O39: =IF(I39=1,IF(N39=1,0,1),0) -> 0 | P39: 1 | Q39: 0 | R39: 0 | S39: 0 | T39: 0 | U39: IPC_026 | V39: 40 | W39: 0.033001269
A40: 0112304 | B40: Pierna de cerdo | C40: Articulo | D40: Alimentos y Bebidas No Alcohólicas | E40: 0 | F40: 0 | G40: 0 | H40: 0 | I40: 1 | J40: 1 | K40: =IF(I40=1,IF(J40=1,0,1),0) -> 0 | L40: 1 | M40: =IF(I40=1,IF(L40=1,0,1),0) -> 0 | N40: 1 | O40: =IF(I40=1,IF(N40=1,0,1),0) -> 0 | P40: 1 | Q40: 0 | R40: 0 | S40: 0 | T40: 1 | U40: IPC_027 | V40: 41 | W40: 0.044233568
...

Sheet comprobacion_codes
A1: id | B1: From online file | C1: Original | D1: Iguales
A2: 1 | B2: Alimentos y Bebidas No Alcohólicas | C2: =dummys!B2 -> Alimentos y Bebidas No Alcohólicas | D2: =C2=B2 -> TRUE
A3: 11 | B3: Alimentos | C3: =dummys!B3 -> Alimentos | D3: =C3=B3 -> TRUE
A4: 111 | B4: Pan y cereales | C4: =dummys!B4 -> Pan y cereales | D4: =C4=B4 -> TRUE
A5: 1111 | B5: Pan | C5: =dummys!B5 -> Pan | D5: =C5=B5 -> TRUE
A6: 111101 | B6: Pan sobado | C6: =dummys!B6 -> Pan sobado | D6: =C6=B6 -> TRUE
A7: 111102 | B7: Pan de agua | C7: =dummys!B7 -> Pan de agua | D7: =C7=B7 -> TRUE
A8: 111104 | B8: Pan Integral | C8: =dummys!B8 -> Pan Integral | D8: =C8=B8 -> TRUE
A9: 1112 | B9: Galletas y productos de panadería | C9: =dummys!B9 -> Galletas y productos de panadería | D9: =C9=B9 -> TRUE
A10: 111201 | B10: Galletas saladas | C10: =dummys!B10 -> Galletas saladas | D10: =C10=B10 -> TRUE
A11: 111202 | B11: Bizcochos | C11: =dummys!B11 -> Bizcochos | D11: =C11=B11 -> TRUE
A12: 111203 | B12: Galletas dulces | C12: =dummys!B12 -> Galletas dulces | D12: =C12=B12 -> TRUE
A13: 111204 | B13: Galletas de harina | C13: =dummys!B13 -> Galletas de harina | D13: =C13=B13 -> TRUE
... A612: 1271105 | B612: Trámite para pasaporte (renovación) | C612: =dummys!B612 -> Trámite para pasaporte (renovación) | D612: =C612=B612 -> TRUE
A613: Z0001 | B613: Indice General | C613: =dummys!B613 -> Indice General | D613: =C613=B613 -> TRUE
